Workbook

Sheet الملخص
A1: ملخص مقارنة المعادلات — نظامنا مقابل نظامهم
A3: المجال | B3: مطابق | C3: شبه مطابق | D3: غير مطابق | E3: عندهم فقط | F3: عندنا فقط | G3: المجموع | H3: نسبة المطابق من المشترك
A4: المسيّر (PAYX) | B4: =COUNTIFS('المقارنة الكاملة'!$B$2:$B$189,$A4,'المقارنة الكاملة'!$H$2:$H$189,B$3) | C4: =COUNTIFS('المقارنة الكاملة'!$B$2:$B$189,$A4,'المقارنة الكاملة'!$H$2:$H$189,C$3) | D4: =COUNTIFS('المقارنة الكاملة'!$B$2:$B$189,$A4,'المقارنة الكاملة'!$H$2:$H$189,D$3) | E4: =COUNTIFS('المقارنة الكاملة'!$B$2:$B$189,$A4,'المقارنة الكاملة'!$H$2:$H$189,E$3) | F4: =COUNTIFS('المقارنة الكاملة'!$B$2:$B$189,$A4,'المقارنة الكاملة'!$H$2:$H$189,F$3) | G4: =SUM(B4:F4) | H4: =IFERROR(B4/(B4+C4+D4),0)
A5: صفوف المسيّر | B5: =COUNTIFS('المقارنة الكاملة'!$B$2:$B$189,$A5,'المقارنة الكاملة'!$H$2:$H$189,B$3) | C5: =COUNTIFS('المقارنة الكاملة'!$B$2:$B$189,$A5,'المقارنة الكاملة'!$H$2:$H$189,C$3) | D5: =COUNTIFS('المقارنة الكاملة'!$B$2:$B$189,$A5,'المقارنة الكاملة'!$H$2:$H$189,D$3) | E5: =COUNTIFS('المقارنة الكاملة'!$B$2:$B$189,$A5,'المقارنة الكاملة'!$H$2:$H$189,E$3) | F5: =COUNTIFS('المقارنة الكاملة'!$B$2:$B$189,$A5,'المقارنة الكاملة'!$H$2:$H$189,F$3) | G5: =SUM(B5:F5) | H5: =IFERROR(B5/(B5+C5+D5),0)
A6: التأمينات | B6: =COUNTIFS('المقارنة الكاملة'!$B$2:$B$189,$A6,'المقارنة الكاملة'!$H$2:$H$189,B$3) | C6: =COUNTIFS('المقارنة الكاملة'!$B$2:$B$189,$A6,'المقارنة الكاملة'!$H$2:$H$189,C$3) | D6: =COUNTIFS('المقارنة الكاملة'!$B$2:$B$189,$A6,'المقارنة الكاملة'!$H$2:$H$189,D$3) | E6: =COUNTIFS('المقارنة الكاملة'!$B$2:$B$189,$A6,'المقارنة الكاملة'!$H$2:$H$189,E$3) | F6: =COUNTIFS('المقارنة الكاملة'!$B$2:$B$189,$A6,'المقارنة الكاملة'!$H$2:$H$189,F$3) | G6: =SUM(B6:F6) | H6: =IFERROR(B6/(B6+C6+D6),0)
A7: بيانات الموظف | B7: =COUNTIFS('المقارنة الكاملة'!$B$2:$B$189,$A7,'المقارنة الكاملة'!$H$2:$H$189,B$3) | C7: =COUNTIFS('المقارنة الكاملة'!$B$2:$B$189,$A7,'المقارنة الكاملة'!$H$2:$H$189,C$3) | D7: =COUNTIFS('المقارنة الكاملة'!$B$2:$B$189,$A7,'المقارنة الكاملة'!$H$2:$H$189,D$3) | E7: =COUNTIFS('المقارنة الكاملة'!$B$2:$B$189,$A7,'المقارنة الكاملة'!$H$2:$H$189,E$3) | F7: =COUNTIFS('المقارنة الكاملة'!$B$2:$B$189,$A7,'المقارنة الكاملة'!$H$2:$H$189,F$3) | G7: =SUM(B7:F7) | H7: =IFERROR(B7/(B7+C7+D7),0)
A8: نهاية الخدمة | B8: =COUNTIFS('المقارنة الكاملة'!$B$2:$B$189,$A8,'المقارنة الكاملة'!$H$2:$H$189,B$3) | C8: =COUNTIFS('المقارنة الكاملة'!$B$2:$B$189,$A8,'المقارنة الكاملة'!$H$2:$H$189,C$3) | D8: =COUNTIFS('المقارنة الكاملة'!$B$2:$B$189,$A8,'المقارنة الكاملة'!$H$2:$H$189,D$3) | E8: =COUNTIFS('المقارنة الكاملة'!$B$2:$B$189,$A8,'المقارنة الكاملة'!$H$2:$H$189,E$3) | F8: =COUNTIFS('المقارنة الكاملة'!$B$2:$B$189,$A8,'المقارنة الكاملة'!$H$2:$H$189,F$3) | G8: =SUM(B8:F8) | H8: =IFERROR(B8/(B8+C8+D8),0)
A9: المخالصة | B9: =COUNTIFS('المقارنة الكاملة'!$B$2:$B$189,$A9,'المقارنة الكاملة'!$H$2:$H$189,B$3) | C9: =COUNTIFS('المقارنة الكاملة'!$B$2:$B$189,$A9,'المقارنة الكاملة'!$H$2:$H$189,C$3) | D9: =COUNTIFS('المقارنة الكاملة'!$B$2:$B$189,$A9,'المقارنة الكاملة'!$H$2:$H$189,D$3) | E9: =COUNTIFS('المقارنة الكاملة'!$B$2:$B$189,$A9,'المقارنة الكاملة'!$H$2:$H$189,E$3) | F9: =COUNTIFS('المقارنة الكاملة'!$B$2:$B$189,$A9,'المقارنة الكاملة'!$H$2:$H$189,F$3) | G9: =SUM(B9:F9) | H9: =IFERROR(B9/(B9+C9+D9),0)
A10: الإجازات | B10: =COUNTIFS('المقارنة الكاملة'!$B$2:$B$189,$A10,'المقارنة الكاملة'!$H$2:$H$189,B$3) | C10: =COUNTIFS('المقارنة الكاملة'!$B$2:$B$189,$A10,'المقارنة الكاملة'!$H$2:$H$189,C$3) | D10: =COUNTIFS('المقارنة الكاملة'!$B$2:$B$189,$A10,'المقارنة الكاملة'!$H$2:$H$189,D$3) | E10: =COUNTIFS('المقارنة الكاملة'!$B$2:$B$189,$A10,'المقارنة الكاملة'!$H$2:$H$189,E$3) | F10: =COUNTIFS('المقارنة الكاملة'!$B$2:$B$189,$A10,'المقارنة الكاملة'!$H$2:$H$189,F$3) | G10: =SUM(B10:F10) | H10: =IFERROR(B10/(B10+C10+D10),0)
A11: الحضور والبصمة | B11: =COUNTIFS('المقارنة الكاملة'!$B$2:$B$189,$A11,'المقارنة الكاملة'!$H$2:$H$189,B$3) | C11: =COUNTIFS('المقارنة الكاملة'!$B$2:$B$189,$A11,'المقارنة الكاملة'!$H$2:$H$189,C$3) | D11: =COUNTIFS('المقارنة الكاملة'!$B$2:$B$189,$A11,'المقارنة الكاملة'!$H$2:$H$189,D$3) | E11: =COUNTIFS('المقارنة الكاملة'!$B$2:$B$189,$A11,'المقارنة الكاملة'!$H$2:$H$189,E$3) | F11: =COUNTIFS('المقارنة الكاملة'!$B$2:$B$189,$A11,'المقارنة الكاملة'!$H$2:$H$189,F$3) | G11: =SUM(B11:F11) | H11: =IFERROR(B11/(B11+C11+D11),0)
A12: لوحة التحكم والتقارير | B12: =COUNTIFS('المقارنة الكاملة'!$B$2:$B$189,$A12,'المقارنة الكاملة'!$H$2:$H$189,B$3) | C12: =COUNTIFS('المقارنة الكاملة'!$B$2:$B$189,$A12,'المقارنة الكاملة'!$H$2:$H$189,C$3) | D12: =COUNTIFS('المقارنة الكاملة'!$B$2:$B$189,$A12,'المقارنة الكاملة'!$H$2:$H$189,D$3) | E12: =COUNTIFS('المقارنة الكاملة'!$B$2:$B$189,$A12,'المقارنة الكاملة'!$H$2:$H$189,E$3) | F12: =COUNTIFS('المقارنة الكاملة'!$B$2:$B$189,$A12,'المقارنة الكاملة'!$H$2:$H$189,F$3) | G12: =SUM(B12:F12) | H12: =IFERROR(B12/(B12+C12+D12),0)
A13: النماذج | B13: =COUNTIFS('المقارنة الكاملة'!$B$2:$B$189,$A13,'المقارنة الكاملة'!$H$2:$H$189,B$3) | C13: =COUNTIFS('المقارنة الكاملة'!$B$2:$B$189,$A13,'المقارنة الكاملة'!$H$2:$H$189,C$3) | D13: =COUNTIFS('المقارنة الكاملة'!$B$2:$B$189,$A13,'المقارنة الكاملة'!$H$2:$H$189,D$3) | E13: =COUNTIFS('المقارنة الكاملة'!$B$2:$B$189,$A13,'المقارنة الكاملة'!$H$2:$H$189,E$3) | F13: =COUNTIFS('المقارنة الكاملة'!$B$2:$B$189,$A13,'المقارنة الكاملة'!$H$2:$H$189,F$3) | G13: =SUM(B13:F13) | H13: =IFERROR(B13/(B13+C13+D13),0)
A14: سير الطلبات | B14: =COUNTIFS('المقارنة الكاملة'!$B$2:$B$189,$A14,'المقارنة الكاملة'!$H$2:$H$189,B$3) | C14: =COUNTIFS('المقارنة الكاملة'!$B$2:$B$189,$A14,'المقارنة الكاملة'!$H$2:$H$189,C$3) | D14: =COUNTIFS('المقارنة الكاملة'!$B$2:$B$189,$A14,'المقارنة الكاملة'!$H$2:$H$189,D$3) | E14: =COUNTIFS('المقارنة الكاملة'!$B$2:$B$189,$A14,'المقارنة الكاملة'!$H$2:$H$189,E$3) | F14: =COUNTIFS('المقارنة الكاملة'!$B$2:$B$189,$A14,'المقارنة الكاملة'!$H$2:$H$189,F$3) | G14: =SUM(B14:F14) | H14: =IFERROR(B14/(B14+C14+D14),0)
A15: ميزات جديدة | B15: =COUNTIFS('المقارنة الكاملة'!$B$2:$B$189,$A15,'المقارنة الكاملة'!$H$2:$H$189,B$3) | C15: =COUNTIFS('المقارنة الكاملة'!$B$2:$B$189,$A15,'المقارنة الكاملة'!$H$2:$H$189,C$3) | D15: =COUNTIFS('المقارنة الكاملة'!$B$2:$B$189,$A15,'المقارنة الكاملة'!$H$2:$H$189,D$3) | E15: =COUNTIFS('المقارنة الكاملة'!$B$2:$B$189,$A15,'المقارنة الكاملة'!$H$2:$H$189,E$3) | F15: =COUNTIFS('المقارنة الكاملة'!$B$2:$B$189,$A15,'المقارنة الكاملة'!$H$2:$H$189,F$3) | G15: =SUM(B15:F15) | H15: =IFERROR(B15/(B15+C15+D15),0)
A16: الدخول والجلسات | B16: =COUNTIFS('المقارنة الكاملة'!$B$2:$B$189,$A16,'المقارنة الكاملة'!$H$2:$H$189,B$3) | C16: =COUNTIFS('المقارنة الكاملة'!$B$2:$B$189,$A16,'المقارنة الكاملة'!$H$2:$H$189,C$3) | D16: =COUNTIFS('المقارنة الكاملة'!$B$2:$B$189,$A16,'المقارنة الكاملة'!$H$2:$H$189,D$3) | E16: =COUNTIFS('المقارنة الكاملة'!$B$2:$B$189,$A16,'المقارنة الكاملة'!$H$2:$H$189,E$3) | F16: =COUNTIFS('المقارنة الكاملة'!$B$2:$B$189,$A16,'المقارنة الكاملة'!$H$2:$H$189,F$3) | G16: =SUM(B16:F16) | H16: =IFERROR(B16/(B16+C16+D16),0)
A17: الإجمالي | B17: =SUM(B4:B16) | C17: =SUM(C4:C16) | D17: =SUM(D4:D16) | E17: =SUM(E4:E16) | F17: =SUM(F4:F16) | G17: =SUM(B17:F17) | H17: =IFERROR(B17/(B17+C17+D17),0)
A19: الألوان: أخضر = مطابق · برتقالي = شبه مطابق (نفس المعادلة وفرق بسيط أو في حالات حدية) · أحمر = غير مطابق · أزرق = عندهم فقط · بنفسجي = عندنا فقط.
A20: نسبة المطابق = المطابق ÷ (المطابق + شبه المطابق + غير المطابق)، أي من المعادلات الموجودة في النظامين.
A21: طريقة الفحص: «تشغيل» = شغّلت معادلاتهم ومعادلاتنا على نفس الأرقام وقارنت النتائج · «قراءة» = مقارنة الكود سطراً بسطر.
A22: الإصدارات: نظامهم = تسليم 18 أكتوبر 2026 (ملفات 17 أكتوبر، مطابق لملف ZIP في التنزيلات). نظامنا = main عند 494998d (14 أكتوبر 2026).
A23: دوال قاعدتهم القديمة مأخوذة من نسخة Supabase بتاريخ 8 أكتوبر؛ نسختهم الحية ربما تغيّرت. الدوال الست الناقصة لا يمكن فحصها.
A24: تصحيحات نظام العمل عندنا: A م.85 · B وعاء المكافأة · C م.77 المحدد · D م.87 · E/F تنبيهات المرضية والإجازات · G التأمينات على السكن الفعلي · J رصيد ما بعد 5 سنوات · K المرن متعدد الجلسات.

Sheet المقارنة الكاملة
A1: م | B1: المجال | C1: المعادلة | D1: نظامهم: المكان | E1: نظامهم: المعادلة | F1: نظامنا: المكان | G1: نظامنا: المعادلة | H1: الحالة | I1: الفرق / السبب | J1: طريقة الفحص
A2: 1 | B2: المسيّر (PAYX) | C2: V الراتب حسب الأيام | D2: هم/HR:engines/payx.js | E2: الأساسي × أيام العمل ÷ أيام الشهر | F2: نحن/موقع:lib/calc/payx.ts | G2: نفسها | H2: مطابق | J2: تشغيل 20,000 حالة
A3: 2 | B3: المسيّر (PAYX) | C3: Y بدل السكن بالأيام | D3: هم/HR:engines/payx.js | E3: الأساسي × نسبة السكن × أيام العمل ÷ أيام الشهر (صفر للتمهير) | F3: نحن/موقع:lib/calc/payx.ts | G3: نفسها | H3: مطابق | J3: تشغيل 20,000 حالة
A4: 3 | B4: المسيّر (PAYX) | C4: Z بدل المواصلات بالأيام | D4: هم/HR:engines/payx.js | E4: الأساسي × نسبة المواصلات × أيام العمل ÷ أيام الشهر (صفر للتمهير) | F4: نحن/موقع:lib/calc/payx.ts | G4: نفسها | H4: مطابق | J4: تشغيل 20,000 حالة
A5: 4 | B5: المسيّر (PAYX) | C5: AA بدل المشروع بالأيام | D5: هم/HR:engines/payx.js | E5: المشروع × أيام العمل ÷ أيام الشهر | F5: نحن/موقع:lib/calc/payx.ts | G5: نفسها | H5: مطابق | J5: تشغيل 20,000 حالة
A6: 5 | B6: المسيّر (PAYX) | C6: AB البدلات الأخرى بالأيام | D6: هم/HR:engines/payx.js | E6: الأخرى × أيام العمل ÷ أيام الشهر | F6: نحن/موقع:lib/calc/payx.ts | G6: نفسها | H6: مطابق | J6: تشغيل 20,000 حالة
A7: 6 | B7: المسيّر (PAYX) | C7: T الراتب شامل البدلات | D7: هم/HR:engines/payx.js | E7: أساسي + سكن + مواصلات + مشروع + أخرى، أو قيمة يدوية | F7: نحن/موقع:lib/calc/payx.ts | G7: نفسها | H7: مطابق | J7: تشغيل 20,000 حالة
A8: 7 | B8: المسيّر (PAYX) | C8: X الإضافي | D8: هم/HR:engines/payx.js | E8: T÷أيام÷8×الساعات + الأساسي÷أيام÷8÷2×الساعات، أو مبلغ يدوي | F8: نحن/موقع:lib/calc/payx.ts | G8: نفسها | H8: مطابق | J8: تشغيل 20,000 حالة
A9: 8 | B9: المسيّر (PAYX) | C9: I نهاية العقد | D9: هم/HR:engines/payx.js | E9: EDATE(المباشرة، مدة العقد بالأشهر) أو آخر يوم | F9: نحن/موقع:lib/calc/payx.ts | G9: نفسها | H9: مطابق | J9: تشغيل 20,000 حالة
A10: 9 | B10: المسيّر (PAYX) | C10: آخر يوم شامل (+1 يوم) | D10: هم/HR:engines/payx.js | E10: آخر يوم يكتبه المستخدم يُحسب كاملاً | F10: نحن/موقع:lib/calc/payx.ts | G10: نفسها | H10: مطابق | J10: تشغيل 20,000 حالة
A11: 10 | B11: المسيّر (PAYX) | C11: AD/AE/AF مدة الخدمة سنة/شهر/يوم | D11: هم/HR:engines/payx.js | E11: DATEDIF مثل Excel (y / ym / md) | F11: نحن/موقع:lib/calc/payx.ts | G11: نفسها | H11: مطابق | J11: تشغيل 20,000 حالة
A12: 11 | B12: المسيّر (PAYX) | C12: K سنوات الخدمة | D12: هم/HR:engines/payx.js | E12: سنة + شهر÷12 + يوم÷360 | F12: نحن/موقع:lib/calc/payx.ts | G12: نفسها | H12: مطابق | J12: تشغيل 20,000 حالة
A13: 12 | B13: المسيّر (PAYX) | C13: N رصيد الإجازة خلال التعاقد | D13: هم/HR:engines/payx.js | E13: K≤5: K×M · بعدها: 105 + (K−5)×30 | F13: نحن/موقع:lib/calc/payx.ts | G13: K≤5: K×M · بعدها: 5×M + (K−5)×max(M,30) | H13: غير مطابق | I13: تصحيح J: يختلف لما الإجازة السنوية ≠ 21 يوم (مثال: عقد 30 يوم و8 سنوات) | J13: تشغيل 3,643 حالة مختلفة
A14: 13 | B14: المسيّر (PAYX) | C14: O ما تم استحقاقه (أيام مأخوذة) | D14: هم/HR:engines/payx.js | E14: يدوي، أو تلقائي لو فيه سبب إنهاء | F14: نحن/موقع:lib/calc/payx.ts | G14: نفسها | H14: مطابق | J14: تشغيل 20,000 حالة
A15: 14 | B15: المسيّر (PAYX) | C15: P الرصيد المستحق | D15: هم/HR:engines/payx.js | E15: N − O | F15: نحن/موقع:lib/calc/payx.ts | G15: N − O | H15: غير مطابق | I15: يتبع فرق N (تصحيح J) | J15: تشغيل
A16: 15 | B16: المسيّر (PAYX) | C16: AC بدل الإجازة | D16: هم/HR:engines/payx.js | E16: P × T ÷ 30 (مع سبب إنهاء) أو يدوي | F16: نحن/موقع:lib/calc/payx.ts | G16: نفسها | H16: غير مطابق | I16: يتبع فرق N (تصحيح J) | J16: تشغيل
A17: 16 | B17: المسيّر (PAYX) | C17: AG تكلفة السنوات | D17: هم/HR:engines/payx.js | E17: ≤5: سنوات×T×0.5 · بعدها: 5×T×0.5 + (سنوات−5)×T — صفر للاستشاري/التمهير/المتدرب | F17: نحن/موقع:lib/calc/payx.ts | G17: نفس المعادلة، صفر للتمهير فقط | H17: شبه مطابق | I17: noEos: الاستشاري والمتدرب يأخذون مكافأة عندنا وليس عندهم | J17: تشغيل 1,385 حالة
A18: 17 | B18: المسيّر (PAYX) | C18: AH تكلفة الشهور | D18: هم/HR:engines/payx.js | E18: ≥5 سنوات: شهور÷12×T · أقل: شهور÷12×T×0.5 | F18: نحن/موقع:lib/calc/payx.ts | G18: نفسها | H18: شبه مطابق | I18: noEos فقط | J18: تشغيل
A19: 18 | B19: المسيّر (PAYX) | C19: AI تكلفة الأيام | D19: هم/HR:engines/payx.js | E19: ≥5 سنوات: أيام÷365×T · أقل: أيام÷360×T×0.5 | F19: نحن/موقع:lib/calc/payx.ts | G19: نفسها | H19: شبه مطابق | I19: noEos فقط | J19: تشغيل
A20: 19 | B20: المسيّر (PAYX) | C20: AJ إجمالي المكافأة | D20: هم/HR:engines/payx.js | E20: AG + AH + AI | F20: نحن/موقع:lib/calc/payx.ts | G20: AG + AH + AI | H20: شبه مطابق | I20: noEos فقط | J20: تشغيل
A21: 20 | B21: المسيّر (PAYX) | C21: أسباب الإنهاء ومعامل المكافأة | D21: هم/HR:engines/payx.js | E21: 8 أسباب · الاستقالة: <2: 0، ≤5: ⅓، ≤10: ⅔، أكثر: كاملة | F21: نحن/موقع:lib/calc/payx.ts | G21: 9 أسباب (+م.87) · الاستقالة: <2: 0، ≤5: ⅓، <10: ⅔، ≥10: كاملة | H21: غير مطابق | I21: تصحيح A (10 سنوات بالضبط) + تصحيح D (م.87) | J21: تشغيل + حالات حدية
A22: 21 | B22: المسيّر (PAYX) | C22: التعرف على سبب الإنهاء من النص | D22: هم/HR:engines/payx.js | E22: مطابقة نص عربي مع توحيد الحروف | F22: نحن/موقع:lib/calc/payx.ts | G22: نفسها + التعرف على م.87 / القوة القاهرة | H22: شبه مطابق | I22: م.87 غير موجودة عندهم | J22: قراءة
A23: 22 | B23: المسيّر (PAYX) | C23: AK مكافأة نهاية الخدمة | D23: هم/HR:engines/payx.js | E23: AJ × معامل السبب | F23: نحن/موقع:lib/calc/payx.ts | G23: AJ × معامل السبب | H23: غير مطابق | I23: يتبع A وD وnoEos | J23: تشغيل 1,464 حالة
A24: 23 | B24: المسيّر (PAYX) | C24: AM إجمالي المستحق | D24: هم/HR:engines/payx.js | E24: V+X+Y+Z+AA+AB+AC+AK | F24: نحن/موقع:lib/calc/payx.ts | G24: نفسها | H24: غير مطابق | I24: يتبع فروق AC وAK | J24: تشغيل 4,814 حالة
A25: 24 | B25: المسيّر (PAYX) | C25: أيام التأمينات | D25: هم/HR:engines/payx.js | E25: =أيام العمل ما لم تُحدد | F25: نحن/موقع:lib/calc/payx.ts | G25: نفسها | H25: مطابق | J25: تشغيل
A26: 25 | B26: المسيّر (PAYX) | C26: AQ الأجر الخاضع للتأمينات | D26: هم/HR:engines/payx.js | E26: min(الحد، (الأساسي + الأساسي×25%) × أيام÷الشهر) | F26: نحن/موقع:lib/calc/payx.ts | G26: min(الحد، (الأساسي + السكن الفعلي) × أيام÷الشهر) | H26: غير مطابق | I26: تصحيح G: يختلف لما السكن ≠ 25% من الأساسي | J26: تشغيل
A27: 26 | B27: المسيّر (PAYX) | C27: AO تأمينات الموظف | D27: هم/HR:engines/payx.js | E27: الأجر الخاضع × نسبة الموظف (يطابق/لا يطابق/55+) | F27: نحن/موقع:lib/calc/payx.ts | G27: نفسها على الأجر الخاضع الفعلي | H27: غير مطابق | I27: تصحيح G | J27: تشغيل 2,613 حالة
A28: 27 | B28: المسيّر (PAYX) | C28: AR تأمينات الشركة | D28: هم/HR:engines/payx.js | E28: الأجر الخاضع × نسبة الشركة، وغير السعودي 2% | F28: نحن/موقع:lib/calc/payx.ts | G28: نفسها على الأجر الخاضع الفعلي | H28: غير مطابق | I28: تصحيح G | J28: تشغيل 4,281 حالة
A29: 28 | B29: المسيّر (PAYX) | C29: عمر 55 سنة | D29: هم/HR:engines/payx.js | E29: DATEDIF(الميلاد، آخر الشهر) ≥ 55 | F29: نحن/موقع:lib/calc/payx.ts | G29: نفسها | H29: مطابق | J29: تشغيل
A30: 29 | B30: المسيّر (PAYX) | C30: AU إجمالي المستقطع | D30: هم/HR:engines/payx.js | E30: أخرى + تأمينات الموظف + سلف + ضريبة مصر + شهداء مصر | F30: نحن/موقع:lib/calc/payx.ts | G30: أخرى + تأمينات الموظف + سلف | H30: شبه مطابق | I30: مطابق للسعودية؛ عندهم بنود مصر | J30: تشغيل
A31: 30 | B31: المسيّر (PAYX) | C31: AV / AW الصافي والصافي بالريال | D31: هم/HR:engines/payx.js | E31: AM − AU ، × سعر الصرف | F31: نحن/موقع:lib/calc/payx.ts | G31: نفسها | H31: غير مطابق | I31: يتبع الفروق أعلاه | J31: تشغيل 7,057 حالة
A32: 31 | B32: المسيّر (PAYX) | C32: ضريبة الدخل والشهداء (مصر) | D32: هم/HR:engines/country.js egCompute | E32: شرائح ضريبية سنوية + 0.05% شهداء | F32: — | G32: — | H32: عندهم فقط | I32: دعم دولة مصر | J32: قراءة
A33: 32 | B33: صفوف المسيّر | C33: من يدخل المسيّر | D33: هم/HR:engines/payrollRows.js buildRows | E33: الحاليون عدا بالساعة و consultant_external و excludeFromPayroll + المنتهون داخل الشهر | F33: نحن/موقع:lib/calc/payroll.ts buildRows | G33: الحاليون عدا بالساعة و exclude_from_payroll و«البوصيري» (اسم مكتوب في الكود) + المنتهون داخل الشهر | H33: شبه مطابق | I33: شرط الاستشاري الخارجي عندهم، واسم مكتوب يدوياً عندنا | J33: قراءة
A34: 33 | B34: صفوف المسيّر | C34: أيام العمل/التأمينات الافتراضية | D34: هم/HR:engines/payrollRows.js defaultInsDays | E34: من يوم المباشرة أو حتى آخر يوم داخل الشهر | F34: نحن/موقع:lib/calc/payroll.ts defaultInsDays | G34: نفسها | H34: مطابق | J34: قراءة
A35: 34 | B35: صفوف المسيّر | C35: حالة التأمينات الافتراضية | D35: هم/HR:engines/payrollRows.js insDefault | E35: غير خاضع / لا يطبق / غير سعودي / يطابق / لا يطابق | F35: نحن/موقع:lib/calc/payroll.ts insDefault | G35: نفسها | H35: مطابق | J35: قراءة
A36: 35 | B36: صفوف المسيّر | C36: القيم الافتراضية عند ↺ | D36: هم/HR:engines/payrollRows.js empDefault | E36: من بيانات الموظف | F36: نحن/موقع:lib/calc/payroll.ts empDefault | G36: نفسها | H36: مطابق | J36: قراءة
A37: 36 | B37: صفوف المسيّر | C37: أيام الإجازة السنوية في الصف | D37: هم/HR:engines/payrollRows.js enrich | E37: من العقد leaveDaysContract (ولمصر حسب العمر والخدمة) | F37: نحن/موقع:lib/calc/payroll.ts enrich | G37: annual_leave_days أو 21 | H37: شبه مطابق | I37: نفس المصدر للسعودية؛ مصر عندهم فقط | J37: قراءة
A38: 37 | B38: صفوف المسيّر | C38: تمرير noEos للمحرك | D38: هم/HR:engines/payrollRows.js recalc | E38: noEos(e) = استشاري/تمهير/متدرب | F38: نحن/موقع:lib/calc/payroll.ts recalc | G38: لا يُمرَّر | H38: غير مطابق | I38: سبب فرق AG..AK | J38: قراءة
A39: 38 | B39: صفوف المسيّر | C39: الإعفاء من التأمينات مع التعديل اليدوي | D39: هم/HR:engines/payrollRows.js recalc | E39: معفى ما لم يغيّر HR الحالة يدوياً | F39: نحن/موقع:lib/calc/payroll.ts recalc | G39: نفسها | H39: مطابق | J39: قراءة
A40: 39 | B40: صفوف المسيّر | C40: أيام العمل من آخر يوم | D40: هم/HR:engines/payrollRows.js autoWork | E40: يوم آخر يوم داخل الشهر، أو صفر قبله | F40: نحن/موقع:lib/calc/payroll.ts autoWork | G40: نفسها | H40: مطابق | J40: قراءة
...
